{
 "cells": [
  {
   "cell_type": "code",
   "execution_count": 1,
   "id": "944b802a-13c3-4ebc-98e3-1960d74db6a3",
   "metadata": {},
   "outputs": [
    {
     "name": "stderr",
     "output_type": "stream",
     "text": [
      "\n",
      "A module that was compiled using NumPy 1.x cannot be run in\n",
      "NumPy 2.3.0 as it may crash. To support both 1.x and 2.x\n",
      "versions of NumPy, modules must be compiled with NumPy 2.0.\n",
      "Some module may need to rebuild instead e.g. with 'pybind11>=2.12'.\n",
      "\n",
      "If you are a user of the module, the easiest solution will be to\n",
      "downgrade to 'numpy<2' or try to upgrade the affected module.\n",
      "We expect that some modules will need time to support NumPy 2.\n",
      "\n",
      "Traceback (most recent call last):  File \"<frozen runpy>\", line 198, in _run_module_as_main\n",
      "  File \"<frozen runpy>\", line 88, in _run_code\n",
      "  File \"/opt/anaconda3/lib/python3.12/site-packages/ipykernel_launcher.py\", line 17, in <module>\n",
      "    app.launch_new_instance()\n",
      "  File \"/opt/anaconda3/lib/python3.12/site-packages/traitlets/config/application.py\", line 1075, in launch_instance\n",
      "    app.start()\n",
      "  File \"/opt/anaconda3/lib/python3.12/site-packages/ipykernel/kernelapp.py\", line 701, in start\n",
      "    self.io_loop.start()\n",
      "  File \"/opt/anaconda3/lib/python3.12/site-packages/tornado/platform/asyncio.py\", line 205, in start\n",
      "    self.asyncio_loop.run_forever()\n",
      "  File \"/opt/anaconda3/lib/python3.12/asyncio/base_events.py\", line 641, in run_forever\n",
      "    self._run_once()\n",
      "  File \"/opt/anaconda3/lib/python3.12/asyncio/base_events.py\", line 1986, in _run_once\n",
      "    handle._run()\n",
      "  File \"/opt/anaconda3/lib/python3.12/asyncio/events.py\", line 88, in _run\n",
      "    self._context.run(self._callback, *self._args)\n",
      "  File \"/opt/anaconda3/lib/python3.12/site-packages/ipykernel/kernelbase.py\", line 534, in dispatch_queue\n",
      "    await self.process_one()\n",
      "  File \"/opt/anaconda3/lib/python3.12/site-packages/ipykernel/kernelbase.py\", line 523, in process_one\n",
      "    await dispatch(*args)\n",
      "  File \"/opt/anaconda3/lib/python3.12/site-packages/ipykernel/kernelbase.py\", line 429, in dispatch_shell\n",
      "    await result\n",
      "  File \"/opt/anaconda3/lib/python3.12/site-packages/ipykernel/kernelbase.py\", line 767, in execute_request\n",
      "    reply_content = await reply_content\n",
      "  File \"/opt/anaconda3/lib/python3.12/site-packages/ipykernel/ipkernel.py\", line 429, in do_execute\n",
      "    res = shell.run_cell(\n",
      "  File \"/opt/anaconda3/lib/python3.12/site-packages/ipykernel/zmqshell.py\", line 549, in run_cell\n",
      "    return super().run_cell(*args, **kwargs)\n",
      "  File \"/opt/anaconda3/lib/python3.12/site-packages/IPython/core/interactiveshell.py\", line 3075, in run_cell\n",
      "    result = self._run_cell(\n",
      "  File \"/opt/anaconda3/lib/python3.12/site-packages/IPython/core/interactiveshell.py\", line 3130, in _run_cell\n",
      "    result = runner(coro)\n",
      "  File \"/opt/anaconda3/lib/python3.12/site-packages/IPython/core/async_helpers.py\", line 128, in _pseudo_sync_runner\n",
      "    coro.send(None)\n",
      "  File \"/opt/anaconda3/lib/python3.12/site-packages/IPython/core/interactiveshell.py\", line 3334, in run_cell_async\n",
      "    has_raised = await self.run_ast_nodes(code_ast.body, cell_name,\n",
      "  File \"/opt/anaconda3/lib/python3.12/site-packages/IPython/core/interactiveshell.py\", line 3517, in run_ast_nodes\n",
      "    if await self.run_code(code, result, async_=asy):\n",
      "  File \"/opt/anaconda3/lib/python3.12/site-packages/IPython/core/interactiveshell.py\", line 3577, in run_code\n",
      "    exec(code_obj, self.user_global_ns, self.user_ns)\n",
      "  File \"/var/folders/kq/zf2878dj6zv6kgvwsrjj3q2m0000gn/T/ipykernel_51694/474790336.py\", line 1, in <module>\n",
      "    import pandas as pd\n",
      "  File \"/opt/anaconda3/lib/python3.12/site-packages/pandas/__init__.py\", line 26, in <module>\n",
      "    from pandas.compat import (\n",
      "  File \"/opt/anaconda3/lib/python3.12/site-packages/pandas/compat/__init__.py\", line 27, in <module>\n",
      "    from pandas.compat.pyarrow import (\n",
      "  File \"/opt/anaconda3/lib/python3.12/site-packages/pandas/compat/pyarrow.py\", line 8, in <module>\n",
      "    import pyarrow as pa\n",
      "  File \"/opt/anaconda3/lib/python3.12/site-packages/pyarrow/__init__.py\", line 65, in <module>\n",
      "    import pyarrow.lib as _lib\n"
     ]
    },
    {
     "ename": "ImportError",
     "evalue": "\nA module that was compiled using NumPy 1.x cannot be run in\nNumPy 2.3.0 as it may crash. To support both 1.x and 2.x\nversions of NumPy, modules must be compiled with NumPy 2.0.\nSome module may need to rebuild instead e.g. with 'pybind11>=2.12'.\n\nIf you are a user of the module, the easiest solution will be to\ndowngrade to 'numpy<2' or try to upgrade the affected module.\nWe expect that some modules will need time to support NumPy 2.\n\n",
     "output_type": "error",
     "traceback": [
      "\u001b[0;31m---------------------------------------------------------------------------\u001b[0m",
      "\u001b[0;31mImportError\u001b[0m                               Traceback (most recent call last)",
      "File \u001b[0;32m/opt/anaconda3/lib/python3.12/site-packages/numpy/core/_multiarray_umath.py:46\u001b[0m, in \u001b[0;36m__getattr__\u001b[0;34m(attr_name)\u001b[0m\n\u001b[1;32m     41\u001b[0m     \u001b[38;5;66;03m# Also print the message (with traceback).  This is because old versions\u001b[39;00m\n\u001b[1;32m     42\u001b[0m     \u001b[38;5;66;03m# of NumPy unfortunately set up the import to replace (and hide) the\u001b[39;00m\n\u001b[1;32m     43\u001b[0m     \u001b[38;5;66;03m# error.  The traceback shouldn't be needed, but e.g. pytest plugins\u001b[39;00m\n\u001b[1;32m     44\u001b[0m     \u001b[38;5;66;03m# seem to swallow it and we should be failing anyway...\u001b[39;00m\n\u001b[1;32m     45\u001b[0m     sys\u001b[38;5;241m.\u001b[39mstderr\u001b[38;5;241m.\u001b[39mwrite(msg \u001b[38;5;241m+\u001b[39m tb_msg)\n\u001b[0;32m---> 46\u001b[0m     \u001b[38;5;28;01mraise\u001b[39;00m \u001b[38;5;167;01mImportError\u001b[39;00m(msg)\n\u001b[1;32m     48\u001b[0m ret \u001b[38;5;241m=\u001b[39m \u001b[38;5;28mgetattr\u001b[39m(_multiarray_umath, attr_name, \u001b[38;5;28;01mNone\u001b[39;00m)\n\u001b[1;32m     49\u001b[0m \u001b[38;5;28;01mif\u001b[39;00m ret \u001b[38;5;129;01mis\u001b[39;00m \u001b[38;5;28;01mNone\u001b[39;00m:\n",
      "\u001b[0;31mImportError\u001b[0m: \nA module that was compiled using NumPy 1.x cannot be run in\nNumPy 2.3.0 as it may crash. To support both 1.x and 2.x\nversions of NumPy, modules must be compiled with NumPy 2.0.\nSome module may need to rebuild instead e.g. with 'pybind11>=2.12'.\n\nIf you are a user of the module, the easiest solution will be to\ndowngrade to 'numpy<2' or try to upgrade the affected module.\nWe expect that some modules will need time to support NumPy 2.\n\n"
     ]
    },
    {
     "name": "stderr",
     "output_type": "stream",
     "text": [
      "\n",
      "A module that was compiled using NumPy 1.x cannot be run in\n",
      "NumPy 2.3.0 as it may crash. To support both 1.x and 2.x\n",
      "versions of NumPy, modules must be compiled with NumPy 2.0.\n",
      "Some module may need to rebuild instead e.g. with 'pybind11>=2.12'.\n",
      "\n",
      "If you are a user of the module, the easiest solution will be to\n",
      "downgrade to 'numpy<2' or try to upgrade the affected module.\n",
      "We expect that some modules will need time to support NumPy 2.\n",
      "\n",
      "Traceback (most recent call last):  File \"<frozen runpy>\", line 198, in _run_module_as_main\n",
      "  File \"<frozen runpy>\", line 88, in _run_code\n",
      "  File \"/opt/anaconda3/lib/python3.12/site-packages/ipykernel_launcher.py\", line 17, in <module>\n",
      "    app.launch_new_instance()\n",
      "  File \"/opt/anaconda3/lib/python3.12/site-packages/traitlets/config/application.py\", line 1075, in launch_instance\n",
      "    app.start()\n",
      "  File \"/opt/anaconda3/lib/python3.12/site-packages/ipykernel/kernelapp.py\", line 701, in start\n",
      "    self.io_loop.start()\n",
      "  File \"/opt/anaconda3/lib/python3.12/site-packages/tornado/platform/asyncio.py\", line 205, in start\n",
      "    self.asyncio_loop.run_forever()\n",
      "  File \"/opt/anaconda3/lib/python3.12/asyncio/base_events.py\", line 641, in run_forever\n",
      "    self._run_once()\n",
      "  File \"/opt/anaconda3/lib/python3.12/asyncio/base_events.py\", line 1986, in _run_once\n",
      "    handle._run()\n",
      "  File \"/opt/anaconda3/lib/python3.12/asyncio/events.py\", line 88, in _run\n",
      "    self._context.run(self._callback, *self._args)\n",
      "  File \"/opt/anaconda3/lib/python3.12/site-packages/ipykernel/kernelbase.py\", line 534, in dispatch_queue\n",
      "    await self.process_one()\n",
      "  File \"/opt/anaconda3/lib/python3.12/site-packages/ipykernel/kernelbase.py\", line 523, in process_one\n",
      "    await dispatch(*args)\n",
      "  File \"/opt/anaconda3/lib/python3.12/site-packages/ipykernel/kernelbase.py\", line 429, in dispatch_shell\n",
      "    await result\n",
      "  File \"/opt/anaconda3/lib/python3.12/site-packages/ipykernel/kernelbase.py\", line 767, in execute_request\n",
      "    reply_content = await reply_content\n",
      "  File \"/opt/anaconda3/lib/python3.12/site-packages/ipykernel/ipkernel.py\", line 429, in do_execute\n",
      "    res = shell.run_cell(\n",
      "  File \"/opt/anaconda3/lib/python3.12/site-packages/ipykernel/zmqshell.py\", line 549, in run_cell\n",
      "    return super().run_cell(*args, **kwargs)\n",
      "  File \"/opt/anaconda3/lib/python3.12/site-packages/IPython/core/interactiveshell.py\", line 3075, in run_cell\n",
      "    result = self._run_cell(\n",
      "  File \"/opt/anaconda3/lib/python3.12/site-packages/IPython/core/interactiveshell.py\", line 3130, in _run_cell\n",
      "    result = runner(coro)\n",
      "  File \"/opt/anaconda3/lib/python3.12/site-packages/IPython/core/async_helpers.py\", line 128, in _pseudo_sync_runner\n",
      "    coro.send(None)\n",
      "  File \"/opt/anaconda3/lib/python3.12/site-packages/IPython/core/interactiveshell.py\", line 3334, in run_cell_async\n",
      "    has_raised = await self.run_ast_nodes(code_ast.body, cell_name,\n",
      "  File \"/opt/anaconda3/lib/python3.12/site-packages/IPython/core/interactiveshell.py\", line 3517, in run_ast_nodes\n",
      "    if await self.run_code(code, result, async_=asy):\n",
      "  File \"/opt/anaconda3/lib/python3.12/site-packages/IPython/core/interactiveshell.py\", line 3577, in run_code\n",
      "    exec(code_obj, self.user_global_ns, self.user_ns)\n",
      "  File \"/var/folders/kq/zf2878dj6zv6kgvwsrjj3q2m0000gn/T/ipykernel_51694/474790336.py\", line 1, in <module>\n",
      "    import pandas as pd\n",
      "  File \"/opt/anaconda3/lib/python3.12/site-packages/pandas/__init__.py\", line 49, in <module>\n",
      "    from pandas.core.api import (\n",
      "  File \"/opt/anaconda3/lib/python3.12/site-packages/pandas/core/api.py\", line 9, in <module>\n",
      "    from pandas.core.dtypes.dtypes import (\n",
      "  File \"/opt/anaconda3/lib/python3.12/site-packages/pandas/core/dtypes/dtypes.py\", line 24, in <module>\n",
      "    from pandas._libs import (\n",
      "  File \"/opt/anaconda3/lib/python3.12/site-packages/pyarrow/__init__.py\", line 65, in <module>\n",
      "    import pyarrow.lib as _lib\n"
     ]
    },
    {
     "ename": "ImportError",
     "evalue": "\nA module that was compiled using NumPy 1.x cannot be run in\nNumPy 2.3.0 as it may crash. To support both 1.x and 2.x\nversions of NumPy, modules must be compiled with NumPy 2.0.\nSome module may need to rebuild instead e.g. with 'pybind11>=2.12'.\n\nIf you are a user of the module, the easiest solution will be to\ndowngrade to 'numpy<2' or try to upgrade the affected module.\nWe expect that some modules will need time to support NumPy 2.\n\n",
     "output_type": "error",
     "traceback": [
      "\u001b[0;31m---------------------------------------------------------------------------\u001b[0m",
      "\u001b[0;31mImportError\u001b[0m                               Traceback (most recent call last)",
      "File \u001b[0;32m/opt/anaconda3/lib/python3.12/site-packages/numpy/core/_multiarray_umath.py:46\u001b[0m, in \u001b[0;36m__getattr__\u001b[0;34m(attr_name)\u001b[0m\n\u001b[1;32m     41\u001b[0m     \u001b[38;5;66;03m# Also print the message (with traceback).  This is because old versions\u001b[39;00m\n\u001b[1;32m     42\u001b[0m     \u001b[38;5;66;03m# of NumPy unfortunately set up the import to replace (and hide) the\u001b[39;00m\n\u001b[1;32m     43\u001b[0m     \u001b[38;5;66;03m# error.  The traceback shouldn't be needed, but e.g. pytest plugins\u001b[39;00m\n\u001b[1;32m     44\u001b[0m     \u001b[38;5;66;03m# seem to swallow it and we should be failing anyway...\u001b[39;00m\n\u001b[1;32m     45\u001b[0m     sys\u001b[38;5;241m.\u001b[39mstderr\u001b[38;5;241m.\u001b[39mwrite(msg \u001b[38;5;241m+\u001b[39m tb_msg)\n\u001b[0;32m---> 46\u001b[0m     \u001b[38;5;28;01mraise\u001b[39;00m \u001b[38;5;167;01mImportError\u001b[39;00m(msg)\n\u001b[1;32m     48\u001b[0m ret \u001b[38;5;241m=\u001b[39m \u001b[38;5;28mgetattr\u001b[39m(_multiarray_umath, attr_name, \u001b[38;5;28;01mNone\u001b[39;00m)\n\u001b[1;32m     49\u001b[0m \u001b[38;5;28;01mif\u001b[39;00m ret \u001b[38;5;129;01mis\u001b[39;00m \u001b[38;5;28;01mNone\u001b[39;00m:\n",
      "\u001b[0;31mImportError\u001b[0m: \nA module that was compiled using NumPy 1.x cannot be run in\nNumPy 2.3.0 as it may crash. To support both 1.x and 2.x\nversions of NumPy, modules must be compiled with NumPy 2.0.\nSome module may need to rebuild instead e.g. with 'pybind11>=2.12'.\n\nIf you are a user of the module, the easiest solution will be to\ndowngrade to 'numpy<2' or try to upgrade the affected module.\nWe expect that some modules will need time to support NumPy 2.\n\n"
     ]
    },
    {
     "name": "stderr",
     "output_type": "stream",
     "text": [
      "\n",
      "A module that was compiled using NumPy 1.x cannot be run in\n",
      "NumPy 2.3.0 as it may crash. To support both 1.x and 2.x\n",
      "versions of NumPy, modules must be compiled with NumPy 2.0.\n",
      "Some module may need to rebuild instead e.g. with 'pybind11>=2.12'.\n",
      "\n",
      "If you are a user of the module, the easiest solution will be to\n",
      "downgrade to 'numpy<2' or try to upgrade the affected module.\n",
      "We expect that some modules will need time to support NumPy 2.\n",
      "\n",
      "Traceback (most recent call last):  File \"<frozen runpy>\", line 198, in _run_module_as_main\n",
      "  File \"<frozen runpy>\", line 88, in _run_code\n",
      "  File \"/opt/anaconda3/lib/python3.12/site-packages/ipykernel_launcher.py\", line 17, in <module>\n",
      "    app.launch_new_instance()\n",
      "  File \"/opt/anaconda3/lib/python3.12/site-packages/traitlets/config/application.py\", line 1075, in launch_instance\n",
      "    app.start()\n",
      "  File \"/opt/anaconda3/lib/python3.12/site-packages/ipykernel/kernelapp.py\", line 701, in start\n",
      "    self.io_loop.start()\n",
      "  File \"/opt/anaconda3/lib/python3.12/site-packages/tornado/platform/asyncio.py\", line 205, in start\n",
      "    self.asyncio_loop.run_forever()\n",
      "  File \"/opt/anaconda3/lib/python3.12/asyncio/base_events.py\", line 641, in run_forever\n",
      "    self._run_once()\n",
      "  File \"/opt/anaconda3/lib/python3.12/asyncio/base_events.py\", line 1986, in _run_once\n",
      "    handle._run()\n",
      "  File \"/opt/anaconda3/lib/python3.12/asyncio/events.py\", line 88, in _run\n",
      "    self._context.run(self._callback, *self._args)\n",
      "  File \"/opt/anaconda3/lib/python3.12/site-packages/ipykernel/kernelbase.py\", line 534, in dispatch_queue\n",
      "    await self.process_one()\n",
      "  File \"/opt/anaconda3/lib/python3.12/site-packages/ipykernel/kernelbase.py\", line 523, in process_one\n",
      "    await dispatch(*args)\n",
      "  File \"/opt/anaconda3/lib/python3.12/site-packages/ipykernel/kernelbase.py\", line 429, in dispatch_shell\n",
      "    await result\n",
      "  File \"/opt/anaconda3/lib/python3.12/site-packages/ipykernel/kernelbase.py\", line 767, in execute_request\n",
      "    reply_content = await reply_content\n",
      "  File \"/opt/anaconda3/lib/python3.12/site-packages/ipykernel/ipkernel.py\", line 429, in do_execute\n",
      "    res = shell.run_cell(\n",
      "  File \"/opt/anaconda3/lib/python3.12/site-packages/ipykernel/zmqshell.py\", line 549, in run_cell\n",
      "    return super().run_cell(*args, **kwargs)\n",
      "  File \"/opt/anaconda3/lib/python3.12/site-packages/IPython/core/interactiveshell.py\", line 3075, in run_cell\n",
      "    result = self._run_cell(\n",
      "  File \"/opt/anaconda3/lib/python3.12/site-packages/IPython/core/interactiveshell.py\", line 3130, in _run_cell\n",
      "    result = runner(coro)\n",
      "  File \"/opt/anaconda3/lib/python3.12/site-packages/IPython/core/async_helpers.py\", line 128, in _pseudo_sync_runner\n",
      "    coro.send(None)\n",
      "  File \"/opt/anaconda3/lib/python3.12/site-packages/IPython/core/interactiveshell.py\", line 3334, in run_cell_async\n",
      "    has_raised = await self.run_ast_nodes(code_ast.body, cell_name,\n",
      "  File \"/opt/anaconda3/lib/python3.12/site-packages/IPython/core/interactiveshell.py\", line 3517, in run_ast_nodes\n",
      "    if await self.run_code(code, result, async_=asy):\n",
      "  File \"/opt/anaconda3/lib/python3.12/site-packages/IPython/core/interactiveshell.py\", line 3577, in run_code\n",
      "    exec(code_obj, self.user_global_ns, self.user_ns)\n",
      "  File \"/var/folders/kq/zf2878dj6zv6kgvwsrjj3q2m0000gn/T/ipykernel_51694/474790336.py\", line 1, in <module>\n",
      "    import pandas as pd\n",
      "  File \"/opt/anaconda3/lib/python3.12/site-packages/pandas/__init__.py\", line 49, in <module>\n",
      "    from pandas.core.api import (\n",
      "  File \"/opt/anaconda3/lib/python3.12/site-packages/pandas/core/api.py\", line 28, in <module>\n",
      "    from pandas.core.arrays import Categorical\n",
      "  File \"/opt/anaconda3/lib/python3.12/site-packages/pandas/core/arrays/__init__.py\", line 1, in <module>\n",
      "    from pandas.core.arrays.arrow import ArrowExtensionArray\n",
      "  File \"/opt/anaconda3/lib/python3.12/site-packages/pandas/core/arrays/arrow/__init__.py\", line 5, in <module>\n",
      "    from pandas.core.arrays.arrow.array import ArrowExtensionArray\n",
      "  File \"/opt/anaconda3/lib/python3.12/site-packages/pandas/core/arrays/arrow/array.py\", line 50, in <module>\n",
      "    from pandas.core import (\n",
      "  File \"/opt/anaconda3/lib/python3.12/site-packages/pandas/core/ops/__init__.py\", line 8, in <module>\n",
      "    from pandas.core.ops.array_ops import (\n",
      "  File \"/opt/anaconda3/lib/python3.12/site-packages/pandas/core/ops/array_ops.py\", line 56, in <module>\n",
      "    from pandas.core.computation import expressions\n",
      "  File \"/opt/anaconda3/lib/python3.12/site-packages/pandas/core/computation/expressions.py\", line 21, in <module>\n",
      "    from pandas.core.computation.check import NUMEXPR_INSTALLED\n",
      "  File \"/opt/anaconda3/lib/python3.12/site-packages/pandas/core/computation/check.py\", line 5, in <module>\n",
      "    ne = import_optional_dependency(\"numexpr\", errors=\"warn\")\n",
      "  File \"/opt/anaconda3/lib/python3.12/site-packages/pandas/compat/_optional.py\", line 135, in import_optional_dependency\n",
      "    module = importlib.import_module(name)\n",
      "  File \"/opt/anaconda3/lib/python3.12/importlib/__init__.py\", line 90, in import_module\n",
      "    return _bootstrap._gcd_import(name[level:], package, level)\n",
      "  File \"/opt/anaconda3/lib/python3.12/site-packages/numexpr/__init__.py\", line 24, in <module>\n",
      "    from numexpr.interpreter import MAX_THREADS, use_vml, __BLOCK_SIZE1__\n"
     ]
    },
    {
     "ename": "AttributeError",
     "evalue": "_ARRAY_API not found",
     "output_type": "error",
     "traceback": [
      "\u001b[0;31m---------------------------------------------------------------------------\u001b[0m",
      "\u001b[0;31mAttributeError\u001b[0m                            Traceback (most recent call last)",
      "\u001b[0;31mAttributeError\u001b[0m: _ARRAY_API not found"
     ]
    },
    {
     "name": "stderr",
     "output_type": "stream",
     "text": [
      "\n",
      "A module that was compiled using NumPy 1.x cannot be run in\n",
      "NumPy 2.3.0 as it may crash. To support both 1.x and 2.x\n",
      "versions of NumPy, modules must be compiled with NumPy 2.0.\n",
      "Some module may need to rebuild instead e.g. with 'pybind11>=2.12'.\n",
      "\n",
      "If you are a user of the module, the easiest solution will be to\n",
      "downgrade to 'numpy<2' or try to upgrade the affected module.\n",
      "We expect that some modules will need time to support NumPy 2.\n",
      "\n",
      "Traceback (most recent call last):  File \"<frozen runpy>\", line 198, in _run_module_as_main\n",
      "  File \"<frozen runpy>\", line 88, in _run_code\n",
      "  File \"/opt/anaconda3/lib/python3.12/site-packages/ipykernel_launcher.py\", line 17, in <module>\n",
      "    app.launch_new_instance()\n",
      "  File \"/opt/anaconda3/lib/python3.12/site-packages/traitlets/config/application.py\", line 1075, in launch_instance\n",
      "    app.start()\n",
      "  File \"/opt/anaconda3/lib/python3.12/site-packages/ipykernel/kernelapp.py\", line 701, in start\n",
      "    self.io_loop.start()\n",
      "  File \"/opt/anaconda3/lib/python3.12/site-packages/tornado/platform/asyncio.py\", line 205, in start\n",
      "    self.asyncio_loop.run_forever()\n",
      "  File \"/opt/anaconda3/lib/python3.12/asyncio/base_events.py\", line 641, in run_forever\n",
      "    self._run_once()\n",
      "  File \"/opt/anaconda3/lib/python3.12/asyncio/base_events.py\", line 1986, in _run_once\n",
      "    handle._run()\n",
      "  File \"/opt/anaconda3/lib/python3.12/asyncio/events.py\", line 88, in _run\n",
      "    self._context.run(self._callback, *self._args)\n",
      "  File \"/opt/anaconda3/lib/python3.12/site-packages/ipykernel/kernelbase.py\", line 534, in dispatch_queue\n",
      "    await self.process_one()\n",
      "  File \"/opt/anaconda3/lib/python3.12/site-packages/ipykernel/kernelbase.py\", line 523, in process_one\n",
      "    await dispatch(*args)\n",
      "  File \"/opt/anaconda3/lib/python3.12/site-packages/ipykernel/kernelbase.py\", line 429, in dispatch_shell\n",
      "    await result\n",
      "  File \"/opt/anaconda3/lib/python3.12/site-packages/ipykernel/kernelbase.py\", line 767, in execute_request\n",
      "    reply_content = await reply_content\n",
      "  File \"/opt/anaconda3/lib/python3.12/site-packages/ipykernel/ipkernel.py\", line 429, in do_execute\n",
      "    res = shell.run_cell(\n",
      "  File \"/opt/anaconda3/lib/python3.12/site-packages/ipykernel/zmqshell.py\", line 549, in run_cell\n",
      "    return super().run_cell(*args, **kwargs)\n",
      "  File \"/opt/anaconda3/lib/python3.12/site-packages/IPython/core/interactiveshell.py\", line 3075, in run_cell\n",
      "    result = self._run_cell(\n",
      "  File \"/opt/anaconda3/lib/python3.12/site-packages/IPython/core/interactiveshell.py\", line 3130, in _run_cell\n",
      "    result = runner(coro)\n",
      "  File \"/opt/anaconda3/lib/python3.12/site-packages/IPython/core/async_helpers.py\", line 128, in _pseudo_sync_runner\n",
      "    coro.send(None)\n",
      "  File \"/opt/anaconda3/lib/python3.12/site-packages/IPython/core/interactiveshell.py\", line 3334, in run_cell_async\n",
      "    has_raised = await self.run_ast_nodes(code_ast.body, cell_name,\n",
      "  File \"/opt/anaconda3/lib/python3.12/site-packages/IPython/core/interactiveshell.py\", line 3517, in run_ast_nodes\n",
      "    if await self.run_code(code, result, async_=asy):\n",
      "  File \"/opt/anaconda3/lib/python3.12/site-packages/IPython/core/interactiveshell.py\", line 3577, in run_code\n",
      "    exec(code_obj, self.user_global_ns, self.user_ns)\n",
      "  File \"/var/folders/kq/zf2878dj6zv6kgvwsrjj3q2m0000gn/T/ipykernel_51694/474790336.py\", line 1, in <module>\n",
      "    import pandas as pd\n",
      "  File \"/opt/anaconda3/lib/python3.12/site-packages/pandas/__init__.py\", line 49, in <module>\n",
      "    from pandas.core.api import (\n",
      "  File \"/opt/anaconda3/lib/python3.12/site-packages/pandas/core/api.py\", line 28, in <module>\n",
      "    from pandas.core.arrays import Categorical\n",
      "  File \"/opt/anaconda3/lib/python3.12/site-packages/pandas/core/arrays/__init__.py\", line 1, in <module>\n",
      "    from pandas.core.arrays.arrow import ArrowExtensionArray\n",
      "  File \"/opt/anaconda3/lib/python3.12/site-packages/pandas/core/arrays/arrow/__init__.py\", line 5, in <module>\n",
      "    from pandas.core.arrays.arrow.array import ArrowExtensionArray\n",
      "  File \"/opt/anaconda3/lib/python3.12/site-packages/pandas/core/arrays/arrow/array.py\", line 64, in <module>\n",
      "    from pandas.core.arrays.masked import BaseMaskedArray\n",
      "  File \"/opt/anaconda3/lib/python3.12/site-packages/pandas/core/arrays/masked.py\", line 60, in <module>\n",
      "    from pandas.core import (\n",
      "  File \"/opt/anaconda3/lib/python3.12/site-packages/pandas/core/nanops.py\", line 52, in <module>\n",
      "    bn = import_optional_dependency(\"bottleneck\", errors=\"warn\")\n",
      "  File \"/opt/anaconda3/lib/python3.12/site-packages/pandas/compat/_optional.py\", line 135, in import_optional_dependency\n",
      "    module = importlib.import_module(name)\n",
      "  File \"/opt/anaconda3/lib/python3.12/importlib/__init__.py\", line 90, in import_module\n",
      "    return _bootstrap._gcd_import(name[level:], package, level)\n",
      "  File \"/opt/anaconda3/lib/python3.12/site-packages/bottleneck/__init__.py\", line 7, in <module>\n",
      "    from .move import (move_argmax, move_argmin, move_max, move_mean, move_median,\n"
     ]
    },
    {
     "ename": "ImportError",
     "evalue": "\nA module that was compiled using NumPy 1.x cannot be run in\nNumPy 2.3.0 as it may crash. To support both 1.x and 2.x\nversions of NumPy, modules must be compiled with NumPy 2.0.\nSome module may need to rebuild instead e.g. with 'pybind11>=2.12'.\n\nIf you are a user of the module, the easiest solution will be to\ndowngrade to 'numpy<2' or try to upgrade the affected module.\nWe expect that some modules will need time to support NumPy 2.\n\n",
     "output_type": "error",
     "traceback": [
      "\u001b[0;31m---------------------------------------------------------------------------\u001b[0m",
      "\u001b[0;31mImportError\u001b[0m                               Traceback (most recent call last)",
      "File \u001b[0;32m/opt/anaconda3/lib/python3.12/site-packages/numpy/core/_multiarray_umath.py:46\u001b[0m, in \u001b[0;36m__getattr__\u001b[0;34m(attr_name)\u001b[0m\n\u001b[1;32m     41\u001b[0m     \u001b[38;5;66;03m# Also print the message (with traceback).  This is because old versions\u001b[39;00m\n\u001b[1;32m     42\u001b[0m     \u001b[38;5;66;03m# of NumPy unfortunately set up the import to replace (and hide) the\u001b[39;00m\n\u001b[1;32m     43\u001b[0m     \u001b[38;5;66;03m# error.  The traceback shouldn't be needed, but e.g. pytest plugins\u001b[39;00m\n\u001b[1;32m     44\u001b[0m     \u001b[38;5;66;03m# seem to swallow it and we should be failing anyway...\u001b[39;00m\n\u001b[1;32m     45\u001b[0m     sys\u001b[38;5;241m.\u001b[39mstderr\u001b[38;5;241m.\u001b[39mwrite(msg \u001b[38;5;241m+\u001b[39m tb_msg)\n\u001b[0;32m---> 46\u001b[0m     \u001b[38;5;28;01mraise\u001b[39;00m \u001b[38;5;167;01mImportError\u001b[39;00m(msg)\n\u001b[1;32m     48\u001b[0m ret \u001b[38;5;241m=\u001b[39m \u001b[38;5;28mgetattr\u001b[39m(_multiarray_umath, attr_name, \u001b[38;5;28;01mNone\u001b[39;00m)\n\u001b[1;32m     49\u001b[0m \u001b[38;5;28;01mif\u001b[39;00m ret \u001b[38;5;129;01mis\u001b[39;00m \u001b[38;5;28;01mNone\u001b[39;00m:\n",
      "\u001b[0;31mImportError\u001b[0m: \nA module that was compiled using NumPy 1.x cannot be run in\nNumPy 2.3.0 as it may crash. To support both 1.x and 2.x\nversions of NumPy, modules must be compiled with NumPy 2.0.\nSome module may need to rebuild instead e.g. with 'pybind11>=2.12'.\n\nIf you are a user of the module, the easiest solution will be to\ndowngrade to 'numpy<2' or try to upgrade the affected module.\nWe expect that some modules will need time to support NumPy 2.\n\n"
     ]
    }
   ],
   "source": [
    "import pandas as pd\n",
    "from data_cleaning.cleaner import DataCleaner # data_cleaning is treated as a python package\n",
    "from uae_info.uaeInfo import UAEInfo \n",
    "from data_saving.dataSaver import DataSaver\n",
    "from database_utils.databaseConfig import Database\n"
   ]
  },
  {
   "cell_type": "code",
   "execution_count": 2,
   "id": "297954ad",
   "metadata": {},
   "outputs": [],
   "source": [
    "class Pipeline:\n",
    "    def __init__(self, raw_data: pd.DataFrame):\n",
    "        self.raw_data = raw_data\n",
    "        self.cleaned_data = None\n",
    "\n",
    "    def data_cleaner(self):\n",
    "        cleaner = DataCleaner(raw_data=self.raw_data)\n",
    "        self.cleaned_data = cleaner.clean_all()\n",
    "\n",
    "\n",
    "    def data_saver(self):\n",
    "        saver = DataSaver()\n",
    "        saver.save_clean_data(df=self.cleaned_data)"
   ]
  },
  {
   "cell_type": "code",
   "execution_count": 3,
   "id": "74f29b4e-7d11-4ad5-b3f6-9d8d1df10da3",
   "metadata": {},
   "outputs": [
    {
     "ename": "AttributeError",
     "evalue": "'NoneType' object has no attribute 'columns'",
     "output_type": "error",
     "traceback": [
      "\u001b[0;31m---------------------------------------------------------------------------\u001b[0m",
      "\u001b[0;31mAttributeError\u001b[0m                            Traceback (most recent call last)",
      "Cell \u001b[0;32mIn[3], line 6\u001b[0m\n\u001b[1;32m      3\u001b[0m raw_dataset \u001b[38;5;241m=\u001b[39m \u001b[38;5;124m\"\u001b[39m\u001b[38;5;124m/Users/pedramjalali/documents/data_analysis/uae_properties/dataset/raw_data/uae_properties.csv\u001b[39m\u001b[38;5;124m\"\u001b[39m\n\u001b[1;32m      5\u001b[0m pl \u001b[38;5;241m=\u001b[39m Pipeline(raw_data\u001b[38;5;241m=\u001b[39mraw_dataset)\n\u001b[0;32m----> 6\u001b[0m pl\u001b[38;5;241m.\u001b[39mdata_cleaner()\n\u001b[1;32m      7\u001b[0m pl\u001b[38;5;241m.\u001b[39mdata_saver()\n",
      "Cell \u001b[0;32mIn[2], line 8\u001b[0m, in \u001b[0;36mPipeline.data_cleaner\u001b[0;34m(self)\u001b[0m\n\u001b[1;32m      6\u001b[0m \u001b[38;5;28;01mdef\u001b[39;00m \u001b[38;5;21mdata_cleaner\u001b[39m(\u001b[38;5;28mself\u001b[39m):\n\u001b[1;32m      7\u001b[0m     cleaner \u001b[38;5;241m=\u001b[39m DataCleaner(raw_data_path\u001b[38;5;241m=\u001b[39m\u001b[38;5;28mself\u001b[39m\u001b[38;5;241m.\u001b[39mraw_data)\n\u001b[0;32m----> 8\u001b[0m     \u001b[38;5;28mself\u001b[39m\u001b[38;5;241m.\u001b[39mcleaned_data \u001b[38;5;241m=\u001b[39m cleaner\u001b[38;5;241m.\u001b[39mclean_all()\n",
      "File \u001b[0;32m~/Documents/data_analysis/uae_properties/data_cleaning/cleaner.py:179\u001b[0m, in \u001b[0;36mDataCleaner.clean_all\u001b[0;34m(self)\u001b[0m\n\u001b[1;32m    178\u001b[0m \u001b[38;5;28;01mdef\u001b[39;00m \u001b[38;5;21mclean_all\u001b[39m(\u001b[38;5;28mself\u001b[39m):\n\u001b[0;32m--> 179\u001b[0m     \u001b[38;5;28mself\u001b[39m\u001b[38;5;241m.\u001b[39mremove_city_from_address()\n\u001b[1;32m    180\u001b[0m     \u001b[38;5;28mself\u001b[39m\u001b[38;5;241m.\u001b[39mnumeric_columns()\n\u001b[1;32m    181\u001b[0m     \u001b[38;5;28mself\u001b[39m\u001b[38;5;241m.\u001b[39mobject_columns()\n",
      "File \u001b[0;32m~/Documents/data_analysis/uae_properties/data_cleaning/cleaner.py:58\u001b[0m, in \u001b[0;36mDataCleaner.remove_city_from_address\u001b[0;34m(self)\u001b[0m\n\u001b[1;32m     57\u001b[0m \u001b[38;5;28;01mdef\u001b[39;00m \u001b[38;5;21mremove_city_from_address\u001b[39m(\u001b[38;5;28mself\u001b[39m):\n\u001b[0;32m---> 58\u001b[0m     \u001b[38;5;28;01mif\u001b[39;00m \u001b[38;5;124m\"\u001b[39m\u001b[38;5;124mAddress\u001b[39m\u001b[38;5;124m\"\u001b[39m \u001b[38;5;129;01min\u001b[39;00m \u001b[38;5;28mself\u001b[39m\u001b[38;5;241m.\u001b[39mdf\u001b[38;5;241m.\u001b[39mcolumns:\n\u001b[1;32m     59\u001b[0m         \u001b[38;5;28;01mfor\u001b[39;00m city \u001b[38;5;129;01min\u001b[39;00m \u001b[38;5;28mself\u001b[39m\u001b[38;5;241m.\u001b[39muae_cities:\n\u001b[1;32m     60\u001b[0m             removing_pattern \u001b[38;5;241m=\u001b[39m \u001b[38;5;124mfr\u001b[39m\u001b[38;5;124m\"\u001b[39m\u001b[38;5;124m,?\u001b[39m\u001b[38;5;124m\\\u001b[39m\u001b[38;5;124ms*\u001b[39m\u001b[38;5;132;01m{\u001b[39;00mcity\u001b[38;5;132;01m}\u001b[39;00m\u001b[38;5;124m\\\u001b[39m\u001b[38;5;124ms*\u001b[39m\u001b[38;5;124m\"\u001b[39m \n",
      "\u001b[0;31mAttributeError\u001b[0m: 'NoneType' object has no attribute 'columns'"
     ]
    }
   ],
   "source": [
    "if __name__ == \"__main__\":\n",
    "\n",
    "    raw_dataset = \"/Users/pedramjalali/documents/data_analysis/uae_properties/dataset/raw_data/uae_properties.csv\"\n",
    "\n",
    "    pl = Pipeline(raw_data=raw_dataset)\n",
    "    pl.data_cleaner()\n",
    "    pl.data_saver()\n",
    "    \n",
    "\n"
   ]
  },
  {
   "cell_type": "code",
   "execution_count": null,
   "id": "bc3baaa3-6e20-4d98-a9a1-106982b6e59e",
   "metadata": {},
   "outputs": [],
   "source": [
    "    # OUTLIER DETECTION\n",
    "    \"\"\"\n",
    "\n",
    "    - Every numeric value column contains high-end and ignorable outliers meaning the distribution is \n",
    "    positively skewed. The majority of the data is clustered toward lower values, \n",
    "    with a few extremely high values pulling the upper end.\n",
    "\n",
    "    - Outliers are not an issue in any case.\n",
    "\n",
    "    \"\"\"\n",
    "\n",
    "    #for column in data.columns:\n",
    "        #cleaner.outlier_detection(column)\n",
    "\n",
    "\n",
    "    # SAVING THE NEW CLEANED DATASET TO 'dataset/cleaned_data/'\n"
   ]
  },
  {
   "cell_type": "markdown",
   "id": "9c27cf2d-5b0a-406e-918c-d6ac518eb7e9",
   "metadata": {},
   "source": [
    "    # LOADING THE SAVED CLEANED DATA TO POSTGRESQL DB\n",
    "\n",
    "    load_to_db = Database()\n",
    "    load_to_db.create_database()\n",
    "    load_to_db.create_engine()\n",
    "    load_to_db.load_to_db()"
   ]
  }
 ],
 "metadata": {
  "kernelspec": {
   "display_name": ".venv",
   "language": "python",
   "name": "python3"
  },
  "language_info": {
   "codemirror_mode": {
    "name": "ipython",
    "version": 3
   },
   "file_extension": ".py",
   "mimetype": "text/x-python",
   "name": "python",
   "nbconvert_exporter": "python",
   "pygments_lexer": "ipython3",
   "version": "3.12.7"
  }
 },
 "nbformat": 4,
 "nbformat_minor": 5
}
